Workbook

Sheet README
A1: Trailbuddies backlog
A2: Prepared 21 Oct 2026 for Steve Gaita. Same story IDs as the Markdown doc and the GitHub issues.
A4: Sheet | B4: What it holds
A5: Backlog | B5: One row per user story. Edit Status, Sprint, Owner and GitHub # here; Points is calculated from Size.
A6: Summary | B6: Counts and points by milestone, priority, status and epic; all formulas, so it updates as you edit Backlog.
A7: Personas | B7: Who the stories are written for.
A8: Screens | B8: Wireframe screen IDs used in the Screens column.
A9: Lists | B9: Allowed values for Priority, Size (with points), Milestone and Status.
A11: Cells you edit | B11: Backlog: Status, Sprint, Owner, GitHub #, Notes (yellow headers). Everything else comes from the story source.
A12: Size → points | B12: XS=1, S=2, M=3, L=5, XL=8 (one point ≈ half a day of Claude-assisted work). Set in Lists.
A13: Example row | B13: MVP-ready stories look like ONB-02: Must · M · MVP · S2 · Status 'To do'.

Sheet Backlog
A1: ID | B1: Epic | C1: Epic name | D1: Title | E1: Persona / role | F1: User story | G1: Acceptance criteria (Given / When / Then) | H1: Priority | I1: Size | J1: Points | K1: Milestone | L1: Sprint | M1: Screens | N1: Status | O1: Owner | P1: GitHub # | Q1: Notes
A2: OFF-01 | B2: OFF | C2: Offline & sync | D2: Installable PWA | E2: Grace (parent) | F2: As Grace (parent), I want to install the app to my tablet's home screen, so that it opens like a normal app. | G2: 1. GIVEN I visit the site on Android Chrome WHEN I choose Install THEN it installs with the app icon and opens full-screen | H2: Must | I2: S | J2: =IFERROR(INDEX(Lists!$B$2:$B$6,MATCH(I2,Lists!$A$2:$A$6,0)),0) -> 2 | K2: MVP | L2: S0 | M2: C01 | N2: To do | O2: Steve | P2: 2
A3: CNT-01 | B3: CNT | C3: Content & subjects | D3: Content schema and validation | E3: Steve (developer) | F3: As Steve (developer), I want a JSON schema for items, units, lessons, trails, buddy scripts and badges, validated in CI, so that content can be added safely without code changes. | G3: 1. GIVEN a unit JSON is missing a required field WHEN CI runs THEN validation fails with the file and field named 2. GIVEN an asset referenced in a unit is missing WHEN CI runs THEN validation fails | H3: Must | I3: M | J3: =IFERROR(INDEX(Lists!$B$2:$B$6,MATCH(I3,Lists!$A$2:$A$6,0)),0) -> 3 | K3: MVP | L3: S0 | N3: To do | O3: Steve | P3: 1
A4: SAF-01 | B4: SAF | C4: Privacy, safety & compliance | D4: Minimal child data | E4: Grace (parent) | F4: As Grace (parent), I want only a nickname, birth month and year and avatar stored about my child, so that their privacy is protected. | G4: 1. GIVEN a learner profile is created WHEN it's stored THEN no surname, email, photo of the child, location or free text is collected | H4: Must | I4: S | J4: =IFERROR(INDEX(Lists!$B$2:$B$6,MATCH(I4,Lists!$A$2:$A$6,0)),0) -> 2 | K4: MVP | L4: S0 | M4: P04 | N4: To do | O4: Steve | P4: 7
A5: SAF-06 | B5: SAF | C5: Privacy, safety & compliance | D5: No third-party trackers | E5: Steve (developer) | F5: As Steve (developer), I want a CI check that blocks third-party analytics and ad SDKs, so that children are never tracked. | G5: 1. GIVEN a PR adds a dependency on a known analytics/ad SDK WHEN CI runs THEN the build fails with an explanation | H5: Must | I5: S | J5: =IFERROR(INDEX(Lists!$B$2:$B$6,MATCH(I5,Lists!$A$2:$A$6,0)),0) -> 2 | K5: MVP | L5: S0 | N5: To do | O5: Steve | P5: 8
A6: OPS-01 | B6: OPS | C6: Platform & DevOps | D6: Monorepo and CI | E6: Steve (developer) | F6: As Steve (developer), I want a pnpm + Turborepo monorepo with lint, tests and content validation on every PR, so that broken code never reaches main. | G6: 1. GIVEN I open a PR WHEN CI runs THEN lint, unit, component, API and content checks run and block merge on failure | H6: Must | I6: M | J6: =IFERROR(INDEX(Lists!$B$2:$B$6,MATCH(I6,Lists!$A$2:$A$6,0)),0) -> 3 | K6: MVP | L6: S0 | N6: To do | O6: Steve | P6: 3
A7: OPS-02 | B7: OPS | C7: Platform & DevOps | D7: Preview deploys | E7: Steve (developer) | F7: As Steve (developer), I want a preview URL for every PR, so that I can check changes on the tablet before merging. | G7: 1. GIVEN I open a PR touching apps/web WHEN the preview deploys THEN the PR shows a link and Playwright smoke tests run against it | H7: Must | I7: S | J7: =IFERROR(INDEX(Lists!$B$2:$B$6,MATCH(I7,Lists!$A$2:$A$6,0)),0) -> 2 | K7: MVP | L7: S0 | N7: To do | O7: Steve | P7: 4
A8: OPS-03 | B8: OPS | C8: Platform & DevOps | D8: API deploy to the VPS | E8: Steve (developer) | F8: As Steve (developer), I want API images built and deployed to the VPS with Docker Compose, so that deploys are one step. | G8: 1. GIVEN I merge to main WHEN CI runs THEN the image is pushed to GHCR and the staging stack pulls and restarts with a health check 2. GIVEN a tag is pushed WHEN the release job runs THEN the database is backed up, migrations run, and production updates | H8: Must | I8: M | J8: =IFERROR(INDEX(Lists!$B$2:$B$6,MATCH(I8,Lists!$A$2:$A$6,0)),0) -> 3 | K8: MVP | L8: S0 | N8: To do | O8: Steve | P8: 5
A9: OPS-04 | B9: OPS | C9: Platform & DevOps | D9: Backups and restore drills | E9: Steve (developer) | F9: As Steve (developer), I want automated database backups to R2 and a monthly restore test, so that I can recover from failure. | G9: 1. GIVEN it's 02:00 WHEN the backup job runs THEN a compressed dump is uploaded to R2 with 30-day retention 2. GIVEN the monthly drill runs WHEN a backup is restored to a scratch database THEN row counts match and the result is logged | H9: Must | I9: S | J9: =IFERROR(INDEX(Lists!$B$2:$B$6,MATCH(I9,Lists!$A$2:$A$6,0)),0) -> 2 | K9: MVP | L9: S0 | N9: To do | O9: Steve | P9: 6
A10: LOC-01 | B10: LOC | C10: Languages & localisation | D10: Every string ready for translation | E10: Steve (developer) | F10: As Steve (developer), I want all UI text, buddy lines and content words stored by key in language files, so that adding a language later needs translation work only, not code changes. | G10: 1. GIVEN a component contains a hard-coded user-facing string WHEN CI runs the i18n lint THEN the PR fails naming the file and line 2. GIVEN a key is missing in a non-English language WHEN the app renders it THEN the English text is shown and a warning is logged in development | H10: Must | I10: M | J10: =IFERROR(INDEX(Lists!$B$2:$B$6,MATCH(I10,Lists!$A$2:$A$6,0)),0) -> 3 | K10: MVP | L10: S0 | N10: To do | O10: Steve | P10: 215
A11: LES-01 | B11: LES | C11: Lessons & exercises | D11: Lesson runner | E11: Amani (Seedling) | F11: As Amani (Seedling), I want a short lesson of 5–8 quick activities with a progress bar, so that I finish before I get bored. | G11: 1. GIVEN I tap a lesson stone WHEN the lesson starts THEN a progress bar shows activities left, and each activity renders the exercise type from the lesson spec 2. GIVEN I tap the exit button WHEN I confirm with the buddy THEN I return to the trail and partial progress is saved for answered items | H11: Must | I11: M | J11: =IFERROR(INDEX(Lists!$B$2:$B$6,MATCH(I11,Lists!$A$2:$A$6,0)),0) -> 3 | K11: MVP | L11: S1 | M11: C07 | N11: To do | O11: Steve | P11: 14
A12: LES-02 | B12: LES | C12: Lessons & exercises | D12: Exercise: listen & tap | E12: Amani (Seedling) | F12: As Amani (Seedling), I want to hear a word and tap the matching picture, so that I learn without reading. | G12: 1. GIVEN the exercise starts WHEN the prompt plays THEN 2–4 pictures show depending on band and the prompt can be replayed with a speaker button 2. GIVEN I tap the right picture WHEN it's checked THEN it's marked correct with sound and the buddy reacts | H12: Must | I12: S | J12: =IFERROR(INDEX(Lists!$B$2:$B$6,MATCH(I12,Lists!$A$2:$A$6,0)),0) -> 2 | K12: MVP | L12: S1 | M12: C07 | N12: To do | O12: Steve | P12: 15
A13: LES-03 | B13: LES | C13: Lessons & exercises | D13: Exercise: match pairs | E13: Zawadi (Sprout) | F13: As Zawadi (Sprout), I want to match pictures with words or sounds by dragging or tapping, so that I connect what I see and hear. | G13: 1. GIVEN 3–5 pairs are shown WHEN I drag or tap-tap a picture to its partner THEN a correct pair locks together; a wrong pair springs back with a hint after 2 misses | H13: Must | I13: S | J13: =IFERROR(INDEX(Lists!$B$2:$B$6,MATCH(I13,Lists!$A$2:$A$6,0)),0) -> 2 | K13: MVP | L13: S1 | M13: C08 | N13: To do | O13: Steve | P13: 16
A14: LES-04 | B14: LES | C14: Lessons & exercises | D14: Exercise: count | E14: Amani (Seedling) | F14: As Amani (Seedling), I want to count objects and tap the number, so that I practise counting. | G14: 1. GIVEN objects are shown WHEN I tap each object THEN it is highlighted and counted aloud; then I tap the matching numeral | H14: Must | I14: S | J14: =IFERROR(INDEX(Lists!$B$2:$B$6,MATCH(I14,Lists!$A$2:$A$6,0)),0) -> 2 | K14: MVP | L14: S1 | M14: C07 | N14: To do | O14: Steve | P14: 17
A15: LES-05 | B15: LES | C15: Lessons & exercises | D15: Exercise: name it | E15: Leo (Explorer) | F15: As Leo (Explorer), I want to see a picture and choose its name, so that I practise recognising words. | G15: 1. GIVEN I'm a reader (Explorer) WHEN the exercise shows THEN options are written words; for non-readers the options are spoken on tap | H15: Must | I15: S | J15: =IFERROR(INDEX(Lists!$B$2:$B$6,MATCH(I15,Lists!$A$2:$A$6,0)),0) -> 2 | K15: MVP | L15: S1 | M15: C07 | N15: To do | O15: Steve | P15: 18
A16: LES-16 | B16: LES | C16: Lessons & exercises | D16: Lesson complete screen | E16: Zawadi (Sprout) | F16: As Zawadi (Sprout), I want a finish screen with my stars and treasures, so that I know how I did and feel rewarded. | G16: 1. GIVEN I finish the last activity WHEN the end screen shows THEN 1–3 stars based on first-try accuracy, treasures earned, and buttons for 'Next lesson' and 'Back to trail' 2. GIVEN I earned a badge in the lesson WHEN the end screen finishes THEN the badge celebration plays next | H16: Must | I16: S | J16: =IFERROR(INDEX(Lists!$B$2:$B$6,MATCH(I16,Lists!$A$2:$A$6,0)),0) -> 2 | K16: MVP | L16: S1 | M16: C12 | N16: To do | O16: Steve | P16: 19
A17: LES-17 | B17: LES | C17: Lessons & exercises | D17: Everything is spoken for non-readers | E17: Amani (Seedling) | F17: As Amani (Seedling), I want every instruction to be spoken, so that I can use the app before I can read. | G17: 1. GIVEN I'm Seedling or Sprout band WHEN any screen shows an instruction THEN it's spoken automatically and a speaker button replays it | H17: Must | I17: S | J17: =IFERROR(INDEX(Lists!$B$2:$B$6,MATCH(I17,Lists!$A$2:$A$6,0)),0) -> 2 | K17: MVP | L17: S1 | M17: C07 | N17: To do | O17: Steve | P17: 20
A18: ADP-01 | B18: ADP | C18: Adaptive learning | D18: Difficulty adjusts automatically | E18: Leo (Explorer) | F18: As Leo (Explorer), I want lessons to get harder when I'm doing well and easier when I'm struggling, so that I'm always challenged but not stuck. | G18: 1. GIVEN I get 3 stars in two consecutive lessons in a subject WHEN the next lesson is generated THEN difficulty within my band increases (more options, fewer hints) 2. GIVEN I get 1 star in two consecutive lessons WHEN the next lesson is generated THEN difficulty decreases | H18: Must | I18: M | J18: =IFERROR(INDEX(Lists!$B$2:$B$6,MATCH(I18,Lists!$A$2:$A$6,0)),0) -> 3 | K18: MVP | L18: S1 | N18: To do | O18: Steve | P18: 9
A19: ADP-03 | B19: ADP | C19: Adaptive learning | D19: Item mastery tracking | E19: Steve (developer) | F19: As Steve (developer), I want a mastery score per child per item, so that weak items can be reviewed and shown to parents. | G19: 1. GIVEN an item is answered WHEN the event is processed THEN seen and first-try-correct counts update and mastery is recalculated in the shared domain package | H19: Must | I19: S | J19: =IFERROR(INDEX(Lists!$B$2:$B$6,MATCH(I19,Lists!$A$2:$A$6,0)),0) -> 2 | K19: MVP | L19: S1 | N19: To do | O19: Steve | P19: 10
A20: ADP-04 | B20: ADP | C20: Adaptive learning | D20: Spaced review | E20: Zawadi (Sprout) | F20: As Zawadi (Sprout), I want things I found hard to come back later, so that I remember them. | G20: 1. GIVEN an item's mastery is below threshold WHEN time passes THEN the item is scheduled for review at 1, 3, 7 and 14 days and included in a review lesson | H20: Must | I20: M | J20: =IFERROR(INDEX(Lists!$B$2:$B$6,MATCH(I20,Lists!$A$2:$A$6,0)),0) -> 3 | K20: MVP | L20: S1 | M20: C05, C10 | N20: To do | O20: Steve | P20: 11
A21: RWD-01 | B21: RWD | C21: Rewards: stars, treasures & shop | D21: Earn stars per lesson | E21: Zawadi (Sprout) | F21: As Zawadi (Sprout), I want to earn 1–3 stars for each lesson, so that I can see how well I did. | G21: 1. GIVEN I finish a lesson WHEN my first-try accuracy is ≥90% THEN I get 3 stars 2. GIVEN accuracy is 60–89% WHEN I finish THEN I get 2 stars; below 60% I still get 1 star 3. GIVEN I replay and do better WHEN I finish THEN the stone keeps my best stars | H21: Must | I21: S | J21: =IFERROR(INDEX(Lists!$B$2:$B$6,MATCH(I21,Lists!$A$2:$A$6,0)),0) -> 2 | K21: MVP | L21: S1 | M21: C12 | N21: To do | O21: Steve | P21: 21
A22: CNT-02 | B22: CNT | C22: Content & subjects | D22: Content packs and versioning | E22: Steve (developer) | F22: As Steve (developer), I want content built into versioned packs per subject and uploaded to storage, so that new lessons can ship without an app release. | G22: 1. GIVEN I run the content build for release 2027.03.1 WHEN it finishes THEN per-subject packs and a manifest are uploaded and clients fetch updated packs on next launch | H22: Must | I22: M | J22: =IFERROR(INDEX(Lists!$B$2:$B$6,MATCH(I22,Lists!$A$2:$A$6,0)),0) -> 3 | K22: MVP | L22: S1 | N22: To do | O22: Steve | P22: 12
A23: CNT-09 | B23: CNT | C23: Content & subjects | D23: Content tooling for writers | E23: Steve (developer) | F23: As Steve (developer), I want a content CLI to validate units, build packs, generate asset prompt sheets and normalise audio, so that making content is fast and consistent. | G23: 1. GIVEN I run 'content-cli assets:prompts animals/farm' WHEN it finishes THEN a prompt sheet listing every item's illustration brief in the style guide is produced 2. GIVEN I run 'content-cli audio:normalise' WHEN it finishes THEN all clips are trimmed and loudness-normalised | H23: Must | I23: M | J23: =IFERROR(INDEX(Lists!$B$2:$B$6,MATCH(I23,Lists!$A$2:$A$6,0)),0) -> 3 | K23: MVP | L23: S1 | N23: To do | O23: Steve | P23: 13
A24: ONB-01 | B24: ONB | C24: Onboarding & accounts | D24: Choose parent or teacher path | E24: Grace (parent) | F24: As Grace (parent), I want to say whether I'm a parent or a teacher when I first open the app, so that I'm taken through the set-up that fits me. | G24: 1. GIVEN I open Trailbuddies for the first time WHEN I see the welcome screen THEN I can choose "I'm a parent" or "I'm a teacher" and a short animated intro of the buddies plays 2. GIVEN I chose "I'm a parent" WHEN I continue THEN I'm taken to sign-up with parent wording throughout | H24: Must | I24: S | J24: =IFERROR(INDEX(Lists!$B$2:$B$6,MATCH(I24,Lists!$A$2:$A$6,0)),0) -> 2 | K24: MVP | L24: S2 | M24: P01 | N24: To do | O24: Steve | P24: 29
A25: ONB-02 | B25: ONB | C25: Onboarding & accounts | D25: Sign up with email magic link | E25: Grace (parent) | F25: As Grace (parent), I want to create an account with just my email and a one-time link, so that I don't have to invent and remember another password. | G25: 1. GIVEN I enter a valid email on sign-up WHEN I tap "Send my link" THEN an email with a sign-in link valid for 15 minutes is sent and the screen tells me to check my inbox 2. GIVEN I open the link on the same or another device WHEN the link is valid THEN I'm signed in and continue onboarding where I left off 3. GIVEN the link has expired or was already used WHEN I open it THEN I see a friendly message and can request a new link | H25: Must | I25: M | J25: =IFERROR(INDEX(Lists!$B$2:$B$6,MATCH(I25,Lists!$A$2:$A$6,0)),0) -> 3 | K25: MVP | L25: S2 | M25: P02, P07 | N25: To do | O25: Steve | P25: 30
A26: ONB-06 | B26: ONB | C26: Onboarding & accounts | D26: Give verifiable parental consent | E26: Grace (parent) | F26: As Grace (parent), I want to read a plain-language summary of what's collected and give consent, so that I know exactly what happens to my children's data before they play. | G26: 1. GIVEN I reach the consent step WHEN I view it THEN I see what is collected, why, how long it's kept and my rights, in plain language with a link to the full policy 2. GIVEN I tick consent and complete the verification step required in my region WHEN I continue THEN a consent record with policy version, timestamp and method is stored 3. GIVEN I haven't consented WHEN I try to add a learner THEN I can't continue until consent is given | H26: Must | I26: M | J26: =IFERROR(INDEX(Lists!$B$2:$B$6,MATCH(I26,Lists!$A$2:$A$6,0)),0) -> 3 | K26: MVP | L26: S2 | M26: P03 | N26: To do | O26: Steve | P26: 31
A27: ONB-07 | B27: ONB | C27: Onboarding & accounts | D27: Add one or more learners | E27: Grace (parent) | F27: As Grace (parent), I want to add each of my children with a first name or nickname, birth month and year and an avatar, so that each child gets their own trail and progress. | G27: 1. GIVEN I'm on "Who's learning?" WHEN I add Amani (born Mar 2023) and Zawadi (born Jun 2020) THEN two profiles are created with age bands Seedling and Sprout set from their birth dates 2. GIVEN I enter a full name WHEN I save THEN I'm reminded that a nickname is enough and only the first name field is stored 3. GIVEN my plan's learner limit is reached WHEN I try to add another THEN I see the limit and an option to upgrade (behind the parent gate) | H27: Must | I27: M | J27: =IFERROR(INDEX(Lists!$B$2:$B$6,MATCH(I27,Lists!$A$2:$A$6,0)),0) -> 3 | K27: MVP | L27: S2 | M27: P04 | N27: To do | O27: Steve | P27: 32
A28: ONB-11 | B28: ONB | C28: Onboarding & accounts | D28: Hand over to the child | E28: Grace (parent) | F28: As Grace (parent), I want a clear hand-over moment at the end of set-up, so that my child can start straight away without me navigating menus. | G28: 1. GIVEN I finish onboarding WHEN I tap "Hand to Amani" THEN the app switches to the child experience and opens Meet the buddies for Amani 2. GIVEN I have several children WHEN I tap "Hand over" THEN the Who's playing? picker opens | H28: Must | I28: XS | J28: =IFERROR(INDEX(Lists!$B$2:$B$6,MATCH(I28,Lists!$A$2:$A$6,0)),0) -> 1 | K28: MVP | L28: S2 | M28: P06, C03 | N28: To do | O28: Steve | P28: 33
A29: ONB-14 | B29: ONB | C29: Onboarding & accounts | D29: Sign out and session handling | E29: Grace (parent) | F29: As Grace (parent), I want sessions to stay signed in on my devices until I sign out, so that I'm not asked to sign in every day but stay in control. | G29: 1. GIVEN I'm signed in WHEN I return within 60 days THEN I remain signed in using a refresh token 2. GIVEN I choose "Sign out of all devices" WHEN I confirm THEN all refresh tokens are revoked and other devices return to the welcome screen | H29: Must | I29: S | J29: =IFERROR(INDEX(Lists!$B$2:$B$6,MATCH(I29,Lists!$A$2:$A$6,0)),0) -> 2 | K29: MVP | L29: S2 | M29: P18 | N29: To do | O29: Steve | P29: 34
A30: FAM-01 | B30: FAM | C30: Family & learner profiles | D30: Who's playing? profile picker | E30: Zawadi (Sprout) | F30: As Zawadi (Sprout), I want to tap my own avatar to start, so that I play on my own trail, not my brother's. | G30: 1. GIVEN the family has two or more learners WHEN the child app opens THEN each learner's avatar and name is shown as a large button and a small 'Grown-ups' button sits in the corner 2. GIVEN I tap my avatar WHEN my profile has no picture password THEN my world map opens | H30: Must | I30: S | J30: =IFERROR(INDEX(Lists!$B$2:$B$6,MATCH(I30,Lists!$A$2:$A$6,0)),0) -> 2 | K30: MVP | L30: S2 | M30: C01 | N30: To do | O30: Steve | P30: 22
A31: FAM-07 | B31: FAM | C31: Family & learner profiles | D31: Switch learner from inside the child app | E31: Grace (parent) | F31: As Grace (parent), I want to switch the active learner quickly, so that siblings can take turns on one tablet. | G31: 1. GIVEN a child is on their map WHEN they tap the avatar in the corner THEN the Who's playing? picker opens without passing the parent gate | H31: Must | I31: XS | J31: =IFERROR(INDEX(Lists!$B$2:$B$6,MATCH(I31,Lists!$A$2:$A$6,0)),0) -> 1 | K31: MVP | L31: S2 | M31: C04, C01 | N31: To do | O31: Steve | P31: 23
A32: MAP-01 | B32: MAP | C32: World map & learning trail | D32: World map of subjects | E32: Amani (Seedling) | F32: As Amani (Seedling), I want a map where every subject is a place I can tap, so that I can choose what to learn by exploring. | G32: 1. GIVEN I'm on my world map WHEN it loads THEN each available subject appears as an illustrated place with its name spoken when tapped once 2. GIVEN my parent picked interests WHEN the map loads THEN those subjects are placed nearest the start | H32: Must | I32: M | J32: =IFERROR(INDEX(Lists!$B$2:$B$6,MATCH(I32,Lists!$A$2:$A$6,0)),0) -> 3 | K32: MVP | L32: S2 | M32: C04 | N32: To do | O32: Steve | P32: 24
A33: MAP-02 | B33: MAP | C33: World map & learning trail | D33: Winding subject trail | E33: Zawadi (Sprout) | F33: As Zawadi (Sprout), I want a winding path of stepping stones for each subject, so that I can see where I am and what comes next. | G33: 1. GIVEN I tap Animals on the map WHEN the trail opens THEN units appear as stage banners and lessons as numbered stones along one continuous path, scrolled to my next lesson 2. GIVEN a lesson is completed WHEN I return to the trail THEN its stone shows 1–3 stars and the next stone glows | H33: Must | I33: L | J33: =IFERROR(INDEX(Lists!$B$2:$B$6,MATCH(I33,Lists!$A$2:$A$6,0)),0) -> 5 | K33: MVP | L33: S2 | M33: C05 | N33: To do | O33: Steve | P33: 25
A34: MAP-09 | B34: MAP | C34: World map & learning trail | D34: Friendly first visit | E34: Amani (Seedling) | F34: As Amani (Seedling), I want my first visit to the map to show me exactly where to start, so that I'm not confused by lots of places. | G34: 1. GIVEN I have no progress yet WHEN my map opens THEN only the first subject place is highlighted, the buddy points to it and says 'Let's start here!', and other places are visible but quieter | H34: Should | I34: S | J34: =IFERROR(INDEX(Lists!$B$2:$B$6,MATCH(I34,Lists!$A$2:$A$6,0)),0) -> 2 | K34: MVP | L34: S2 | M34: C29 | N34: To do | O34: Steve | P34: 216
A35: PAR-06 | B35: PAR | C35: Parent dashboard & controls | D35: Parent gate | E35: Grace (parent) | F35: As Grace (parent), I want the grown-up zone behind a gate a young child can't pass, so that my child can't change settings or buy things. | G35: 1. GIVEN a child taps 'Grown-ups' WHEN the gate shows THEN a sum such as 'What is 7 × 3?' with number buttons, or 'Hold for 3 seconds' as the accessible option, must be completed 2. GIVEN any learner on the account is 8 or older WHEN I open settings THEN I'm prompted to set a 4-digit PIN that replaces the sum | H35: Must | I35: S | J35: =IFERROR(INDEX(Lists!$B$2:$B$6,MATCH(I35,Lists!$A$2:$A$6,0)),0) -> 2 | K35: MVP | L35: S2 | M35: C24 | N35: To do | O35: Steve | P35: 35
... A37: OFF-04 | B37: OFF | C37: Offline & sync | D37: Sync across devices | E37: Grace (parent) | F37: As Grace (parent), I want progress on any device to appear on all others, so that my children can switch devices. | G37: 1. GIVEN Zawadi plays on the tablet WHEN I open my phone THEN her new stars and badges show after sync (within a minute when online) | H37: Must | I37: M | J37: =IFERROR(INDEX(Lists!$B$2:$B$6,MATCH(I37,Lists!$A$2:$A$6,0)),0) -> 3 | K37: MVP | L37: S2 | M37: P08 | N37: To do | O37: Steve | P37: 27
A38: OFF-05 | B38: OFF | C38: Offline & sync | D38: Conflict handling for edits | E38: Steve (developer) | F38: As Steve (developer), I want grown-up edits to merge with last-write-wins using server timestamps, so that edits from two devices don't corrupt data. | G38: 1. GIVEN a lesson is edited offline on two devices WHEN both sync THEN the later edit wins and the earlier is kept in history for 30 days | H38: Must | I38: S | J38: =IFERROR(INDEX(Lists!$B$2:$B$6,MATCH(I38,Lists!$A$2:$A$6,0)),0) -> 2 | K38: MVP | L38: S2 | N38: To do | O38: Steve | P38: 28
A39: BUD-01 | B39: BUD | C39: Buddy tutor | D39: Choose a buddy | E39: Amani (Seedling) | F39: As Amani (Seedling), I want to meet the buddies and pick the one I like, so that I have a friend who helps me learn. | G39: 1. GIVEN I'm a new learner WHEN Meet the buddies opens THEN each buddy waves and introduces itself in its own voice when tapped 2. GIVEN I tap "Pick me!" on Zip WHEN I confirm THEN Zip becomes my buddy and appears on my map 3. GIVEN only one buddy is available (MVP) WHEN I view the screen THEN other buddies show as 'coming soon' and can't be selected | H39: Must | I39: S | J39: =IFERROR(INDEX(Lists!$B$2:$B$6,MATCH(I39,Lists!$A$2:$A$6,0)),0) -> 2 | K39: MVP | L39: S3 | M39: C03 | N39: To do | O39: Steve | P39: 36
A40: BUD-03 | B40: BUD | C40: Buddy tutor | D40: Buddy greets me by name | E40: Amani (Seedling) | F40: As Amani (Seedling), I want my buddy to say hello using my name, so that it feels like my own friend. | G40: 1. GIVEN I open my map WHEN it's my first visit today THEN the buddy greets me by name (parent recording if one exists, otherwise the voice pack or device voice) and mentions what we did last time | H40: Must | I40: S | J40: =IFERROR(INDEX(Lists!$B$2:$B$6,MATCH(I40,Lists!$A$2:$A$6,0)),0) -> 2 | K40: MVP | L40: S3 | M40: C04 | N40: To do | O40: Steve | P40: 37
A41: BUD-04 | B41: BUD | C41: Buddy tutor | D41: Buddy introduces new concepts | E41: Amani (Seedling) | F41: As Amani (Seedling), I want my buddy to show and say each new thing before asking me, so that I'm never asked something I haven't seen. | G41: 1. GIVEN a lesson contains an item I haven't seen WHEN the item first appears THEN the buddy shows the picture, says the word and one fun fact before any question about it | H41: Must | I41: S | J41: =IFERROR(INDEX(Lists!$B$2:$B$6,MATCH(I41,Lists!$A$2:$A$6,0)),0) -> 2 | K41: MVP | L41: S3 | M41: C07 | N41: To do | O41: Steve | P41: 38
...

Sheet Summary
A1: Backlog summary (all formulas: updates as the Backlog sheet changes)
A3: Milestone | B3: Title | C3: Stories | D3: Must | E3: Should | F3: Could | G3: Points | H3: Done (stories) | I3: Done (points) | J3: % points done
A4: MVP | B4: Phase 1 — MVP (closed web beta) | C4: =COUNTIFS(Backlog!$K$2:$K$229,A4) -> 110 | D4: =COUNTIFS(Backlog!$K$2:$K$229,A4,Backlog!$H$2:$H$229,"Must") -> 100 | E4: =COUNTIFS(Backlog!$K$2:$K$229,A4,Backlog!$H$2:$H$229,"Should") -> 10 | F4: =COUNTIFS(Backlog!$K$2:$K$229,A4,Backlog!$H$2:$H$229,"Could") -> 0 | G4: =SUMIFS(Backlog!$J$2:$J$229,Backlog!$K$2:$K$229,A4) -> 264 | H4: =COUNTIFS(Backlog!$K$2:$K$229,A4,Backlog!$N$2:$N$229,"Done") -> 0 | I4: =SUMIFS(Backlog!$J$2:$J$229,Backlog!$K$2:$K$229,A4,Backlog!$N$2:$N$229,"Done") -> 0 | J4: =IF(G4=0,0,I4/G4) -> 0
A5: P2 | B5: Phase 2 — Beta iteration + Classroom | C5: =COUNTIFS(Backlog!$K$2:$K$229,A5) -> 51 | D5: =COUNTIFS(Backlog!$K$2:$K$229,A5,Backlog!$H$2:$H$229,"Must") -> 28 | E5: =COUNTIFS(Backlog!$K$2:$K$229,A5,Backlog!$H$2:$H$229,"Should") -> 18 | F5: =COUNTIFS(Backlog!$K$2:$K$229,A5,Backlog!$H$2:$H$229,"Could") -> 5 | G5: =SUMIFS(Backlog!$J$2:$J$229,Backlog!$K$2:$K$229,A5) -> 130 | H5: =COUNTIFS(Backlog!$K$2:$K$229,A5,Backlog!$N$2:$N$229,"Done") -> 0 | I5: =SUMIFS(Backlog!$J$2:$J$229,Backlog!$K$2:$K$229,A5,Backlog!$N$2:$N$229,"Done") -> 0 | J5: =IF(G5=0,0,I5/G5) -> 0
A6: P3 | B6: Phase 3 — React Native Android app | C6: =COUNTIFS(Backlog!$K$2:$K$229,A6) -> 6 | D6: =COUNTIFS(Backlog!$K$2:$K$229,A6,Backlog!$H$2:$H$229,"Must") -> 6 | E6: =COUNTIFS(Backlog!$K$2:$K$229,A6,Backlog!$H$2:$H$229,"Should") -> 0 | F6: =COUNTIFS(Backlog!$K$2:$K$229,A6,Backlog!$H$2:$H$229,"Could") -> 0 | G6: =SUMIFS(Backlog!$J$2:$J$229,Backlog!$K$2:$K$229,A6) -> 25 | H6: =COUNTIFS(Backlog!$K$2:$K$229,A6,Backlog!$N$2:$N$229,"Done") -> 0 | I6: =SUMIFS(Backlog!$J$2:$J$229,Backlog!$K$2:$K$229,A6,Backlog!$N$2:$N$229,"Done") -> 0 | J6: =IF(G6=0,0,I6/G6) -> 0
A7: P4 | B7: Phase 4 — Breadth + public launch | C7: =COUNTIFS(Backlog!$K$2:$K$229,A7) -> 38 | D7: =COUNTIFS(Backlog!$K$2:$K$229,A7,Backlog!$H$2:$H$229,"Must") -> 11 | E7: =COUNTIFS(Backlog!$K$2:$K$229,A7,Backlog!$H$2:$H$229,"Should") -> 17 | F7: =COUNTIFS(Backlog!$K$2:$K$229,A7,Backlog!$H$2:$H$229,"Could") -> 10 | G7: =SUMIFS(Backlog!$J$2:$J$229,Backlog!$K$2:$K$229,A7) -> 117 | H7: =COUNTIFS(Backlog!$K$2:$K$229,A7,Backlog!$N$2:$N$229,"Done") -> 0 | I7: =SUMIFS(Backlog!$J$2:$J$229,Backlog!$K$2:$K$229,A7,Backlog!$N$2:$N$229,"Done") -> 0 | J7: =IF(G7=0,0,I7/G7) -> 0
A8: P5 | B8: Phase 5 — Post-launch | C8: =COUNTIFS(Backlog!$K$2:$K$229,A8) -> 23 | D8: =COUNTIFS(Backlog!$K$2:$K$229,A8,Backlog!$H$2:$H$229,"Must") -> 0 | E8: =COUNTIFS(Backlog!$K$2:$K$229,A8,Backlog!$H$2:$H$229,"Should") -> 13 | F8: =COUNTIFS(Backlog!$K$2:$K$229,A8,Backlog!$H$2:$H$229,"Could") -> 10 | G8: =SUMIFS(Backlog!$J$2:$J$229,Backlog!$K$2:$K$229,A8) -> 106 | H8: =COUNTIFS(Backlog!$K$2:$K$229,A8,Backlog!$N$2:$N$229,"Done") -> 0 | I8: =SUMIFS(Backlog!$J$2:$J$229,Backlog!$K$2:$K$229,A8,Backlog!$N$2:$N$229,"Done") -> 0 | J8: =IF(G8=0,0,I8/G8) -> 0
A9: Total | C9: =SUM(C4:C8) -> 228 | D9: =SUM(D4:D8) -> 145 | E9: =SUM(E4:E8) -> 58 | F9: =SUM(F4:F8) -> 25 | G9: =SUM(G4:G8) -> 642 | H9: =SUM(H4:H8) -> 0 | I9: =SUM(I4:I8) -> 0 | J9: =IF(G9=0,0,I9/G9) -> 0
A11: MVP points per sprint (8 sprints) | C11: =G4/8 -> 33
A13: Epic | B13: Name | C13: Stories | D13: Points | E13: Done (points) | F13: % done
A14: ONB | B14: Onboarding & accounts | C14: =COUNTIFS(Backlog!$B$2:$B$229,A14) -> 14 | D14: =SUMIFS(Backlog!$J$2:$J$229,Backlog!$B$2:$B$229,A14) -> 31 | E14: =SUMIFS(Backlog!$J$2:$J$229,Backlog!$B$2:$B$229,A14,Backlog!$N$2:$N$229,"Done") -> 0 | F14: =IF(D14=0,0,E14/D14) -> 0
A15: FAM | B15: Family & learner profiles | C15: =COUNTIFS(Backlog!$B$2:$B$229,A15) -> 8 | D15: =SUMIFS(Backlog!$J$2:$J$229,Backlog!$B$2:$B$229,A15) -> 16 | E15: =SUMIFS(Backlog!$J$2:$J$229,Backlog!$B$2:$B$229,A15,Backlog!$N$2:$N$229,"Done") -> 0 | F15: =IF(D15=0,0,E15/D15) -> 0
A16: BUD | B16: Buddy tutor | C16: =COUNTIFS(Backlog!$B$2:$B$229,A16) -> 11 | D16: =SUMIFS(Backlog!$J$2:$J$229,Backlog!$B$2:$B$229,A16) -> 26 | E16: =SUMIFS(Backlog!$J$2:$J$229,Backlog!$B$2:$B$229,A16,Backlog!$N$2:$N$229,"Done") -> 0 | F16: =IF(D16=0,0,E16/D16) -> 0
A17: MAP | B17: World map & learning trail | C17: =COUNTIFS(Backlog!$B$2:$B$229,A17) -> 9 | D17: =SUMIFS(Backlog!$J$2:$J$229,Backlog!$B$2:$B$229,A17) -> 25 | E17: =SUMIFS(Backlog!$J$2:$J$229,Backlog!$B$2:$B$229,A17,Backlog!$N$2:$N$229,"Done") -> 0 | F17: =IF(D17=0,0,E17/D17) -> 0
A18: LES | B18: Lessons & exercises | C18: =COUNTIFS(Backlog!$B$2:$B$229,A18) -> 19 | D18: =SUMIFS(Backlog!$J$2:$J$229,Backlog!$B$2:$B$229,A18) -> 52 | E18: =SUMIFS(Backlog!$J$2:$J$229,Backlog!$B$2:$B$229,A18,Backlog!$N$2:$N$229,"Done") -> 0 | F18: =IF(D18=0,0,E18/D18) -> 0
A19: ADP | B19: Adaptive learning | C19: =COUNTIFS(Backlog!$B$2:$B$229,A19) -> 7 | D19: =SUMIFS(Backlog!$J$2:$J$229,Backlog!$B$2:$B$229,A19) -> 17 | E19: =SUMIFS(Backlog!$J$2:$J$229,Backlog!$B$2:$B$229,A19,Backlog!$N$2:$N$229,"Done") -> 0 | F19: =IF(D19=0,0,E19/D19) -> 0
A20: GAM | B20: Games | C20: =COUNTIFS(Backlog!$B$2:$B$229,A20) -> 9 | D20: =SUMIFS(Backlog!$J$2:$J$229,Backlog!$B$2:$B$229,A20) -> 29 | E20: =SUMIFS(Backlog!$J$2:$J$229,Backlog!$B$2:$B$229,A20,Backlog!$N$2:$N$229,"Done") -> 0 | F20: =IF(D20=0,0,E20/D20) -> 0
A21: RWD | B21: Rewards: stars, treasures & shop | C21: =COUNTIFS(Backlog!$B$2:$B$229,A21) -> 10 | D21: =SUMIFS(Backlog!$J$2:$J$229,Backlog!$B$2:$B$229,A21) -> 27 | E21: =SUMIFS(Backlog!$J$2:$J$229,Backlog!$B$2:$B$229,A21,Backlog!$N$2:$N$229,"Done") -> 0 | F21: =IF(D21=0,0,E21/D21) -> 0
A22: BDG | B22: Badges & achievements | C22: =COUNTIFS(Backlog!$B$2:$B$229,A22) -> 7 | D22: =SUMIFS(Backlog!$J$2:$J$229,Backlog!$B$2:$B$229,A22) -> 15 | E22: =SUMIFS(Backlog!$J$2:$J$229,Backlog!$B$2:$B$229,A22,Backlog!$N$2:$N$229,"Done") -> 0 | F22: =IF(D22=0,0,E22/D22) -> 0
A23: BST | B23: Badge Studio & Wish list | C23: =COUNTIFS(Backlog!$B$2:$B$229,A23) -> 8 | D23: =SUMIFS(Backlog!$J$2:$J$229,Backlog!$B$2:$B$229,A23) -> 22 | E23: =SUMIFS(Backlog!$J$2:$J$229,Backlog!$B$2:$B$229,A23,Backlog!$N$2:$N$229,"Done") -> 0 | F23: =IF(D23=0,0,E23/D23) -> 0
A24: BLD | B24: Lesson Builder & custom trails | C24: =COUNTIFS(Backlog!$B$2:$B$229,A24) -> 16 | D24: =SUMIFS(Backlog!$J$2:$J$229,Backlog!$B$2:$B$229,A24) -> 44 | E24: =SUMIFS(Backlog!$J$2:$J$229,Backlog!$B$2:$B$229,A24,Backlog!$N$2:$N$229,"Done") -> 0 | F24: =IF(D24=0,0,E24/D24) -> 0
A25: SHR | B25: Sharing by code | C25: =COUNTIFS(Backlog!$B$2:$B$229,A25) -> 5 | D25: =SUMIFS(Backlog!$J$2:$J$229,Backlog!$B$2:$B$229,A25) -> 12 | E25: =SUMIFS(Backlog!$J$2:$J$229,Backlog!$B$2:$B$229,A25,Backlog!$N$2:$N$229,"Done") -> 0 | F25: =IF(D25=0,0,E25/D25) -> 0
... A42: HLP | B42: Help & support | C42: =COUNTIFS(Backlog!$B$2:$B$229,A42) -> 3 | D42: =SUMIFS(Backlog!$J$2:$J$229,Backlog!$B$2:$B$229,A42) -> 7 | E42: =SUMIFS(Backlog!$J$2:$J$229,Backlog!$B$2:$B$229,A42,Backlog!$N$2:$N$229,"Done") -> 0 | F42: =IF(D42=0,0,E42/D42) -> 0
A44: Sprint | C44: Stories | D44: Points | E44: Done (points)
A45: S0 | C45: =COUNTIFS(Backlog!$L$2:$L$229,A45) -> 9 | D45: =SUMIFS(Backlog!$J$2:$J$229,Backlog!$L$2:$L$229,A45) -> 22 | E45: =SUMIFS(Backlog!$J$2:$J$229,Backlog!$L$2:$L$229,A45,Backlog!$N$2:$N$229,"Done") -> 0
A46: S1 | C46: =COUNTIFS(Backlog!$L$2:$L$229,A46) -> 13 | D46: =SUMIFS(Backlog!$J$2:$J$229,Backlog!$L$2:$L$229,A46) -> 31 | E46: =SUMIFS(Backlog!$J$2:$J$229,Backlog!$L$2:$L$229,A46,Backlog!$N$2:$N$229,"Done") -> 0
A47: S2 | C47: =COUNTIFS(Backlog!$L$2:$L$229,A47) -> 15 | D47: =SUMIFS(Backlog!$J$2:$J$229,Backlog!$L$2:$L$229,A47) -> 39 | E47: =SUMIFS(Backlog!$J$2:$J$229,Backlog!$L$2:$L$229,A47,Backlog!$N$2:$N$229,"Done") -> 0
A48: S3 | C48: =COUNTIFS(Backlog!$L$2:$L$229,A48) -> 13 | D48: =SUMIFS(Backlog!$J$2:$J$229,Backlog!$L$2:$L$229,A48) -> 29 | E48: =SUMIFS(Backlog!$J$2:$J$229,Backlog!$L$2:$L$229,A48,Backlog!$N$2:$N$229,"Done") -> 0
A49: S4 | C49: =COUNTIFS(Backlog!$L$2:$L$229,A49) -> 16 | D49: =SUMIFS(Backlog!$J$2:$J$229,Backlog!$L$2:$L$229,A49) -> 37 | E49: =SUMIFS(Backlog!$J$2:$J$229,Backlog!$L$2:$L$229,A49,Backlog!$N$2:$N$229,"Done") -> 0
A50: S5 | C50: =COUNTIFS(Backlog!$L$2:$L$229,A50) -> 15 | D50: =SUMIFS(Backlog!$J$2:$J$229,Backlog!$L$2:$L$229,A50) -> 37 | E50: =SUMIFS(Backlog!$J$2:$J$229,Backlog!$L$2:$L$229,A50,Backlog!$N$2:$N$229,"Done") -> 0
A51: S6 | C51: =COUNTIFS(Backlog!$L$2:$L$229,A51) -> 14 | D51: =SUMIFS(Backlog!$J$2:$J$229,Backlog!$L$2:$L$229,A51) -> 36 | E51: =SUMIFS(Backlog!$J$2:$J$229,Backlog!$L$2:$L$229,A51,Backlog!$N$2:$N$229,"Done") -> 0
A52: S7 | C52: =COUNTIFS(Backlog!$L$2:$L$229,A52) -> 15 | D52: =SUMIFS(Backlog!$J$2:$J$229,Backlog!$L$2:$L$229,A52) -> 33 | E52: =SUMIFS(Backlog!$J$2:$J$229,Backlog!$L$2:$L$229,A52,Backlog!$N$2:$N$229,"Done") -> 0
A53: S8 | C53: =COUNTIFS(Backlog!$L$2:$L$229,A53) -> 10 | D53: =SUMIFS(Backlog!$J$2:$J$229,Backlog!$L$2:$L$229,A53) -> 24 | E53: =SUMIFS(Backlog!$J$2:$J$229,Backlog!$L$2:$L$229,A53,Backlog!$N$2:$N$229,"Done") -> 0
A54: S9 | C54: =COUNTIFS(Backlog!$L$2:$L$229,A54) -> 9 | D54: =SUMIFS(Backlog!$J$2:$J$229,Backlog!$L$2:$L$229,A54) -> 23 | E54: =SUMIFS(Backlog!$J$2:$J$229,Backlog!$L$2:$L$229,A54,Backlog!$N$2:$N$229,"Done") -> 0
A55: S10 | C55: =COUNTIFS(Backlog!$L$2:$L$229,A55) -> 12 | D55: =SUMIFS(Backlog!$J$2:$J$229,Backlog!$L$2:$L$229,A55) -> 33 | E55: =SUMIFS(Backlog!$J$2:$J$229,Backlog!$L$2:$L$229,A55,Backlog!$N$2:$N$229,"Done") -> 0
A56: S11 | C56: =COUNTIFS(Backlog!$L$2:$L$229,A56) -> 20 | D56: =SUMIFS(Backlog!$J$2:$J$229,Backlog!$L$2:$L$229,A56) -> 50 | E56: =SUMIFS(Backlog!$J$2:$J$229,Backlog!$L$2:$L$229,A56,Backlog!$N$2:$N$229,"Done") -> 0
... A69: S24 | C69: =COUNTIFS(Backlog!$L$2:$L$229,A69) -> 0 | D69: =SUMIFS(Backlog!$J$2:$J$229,Backlog!$L$2:$L$229,A69) -> 0 | E69: =SUMIFS(Backlog!$J$2:$J$229,Backlog!$L$2:$L$229,A69,Backlog!$N$2:$N$229,"Done") -> 0

Sheet Personas
A1: Name | B1: Age | C1: Role | D1: Summary | E1: Needs | F1: Frustrations
A2: Amani | B2: 3 | C2: Learner (Seedling, 3–4) | D2: Can't read yet. Loves animals and tapping things. Plays on the family's budget Android tablet, usually for 10–15 minutes after nursery, with Mum nearby. | E2: Everything spoken aloud; big targets; no failure states; lots of praise; quick wins. | F2: Small buttons, text instructions, anything that takes too long to load.
A3: Zawadi | B3: 6 | C3: Learner (Sprout, 5–6) | D3: Amani's older sister. Learning to read and count to 100. Very motivated by collecting stickers and dressing up her buddy. Plays at home and in class. | E3: Visible progress; rewards to save up for; feeling 'big' compared with her little brother. | F3: Repeating lessons she already knows; her brother playing on her profile.
A4: Leo | B4: 8 | C4: Learner (Explorer, 7–8) | D4: Confident reader, obsessed with space and football. Likes challenges and getting things right first time. | E4: Harder questions, real facts, a sense of mastery; less babyish feedback. | F4: Being made to do easy stuff; slow celebrations that stop him moving on.
A5: Nia | B5: 11 | C5: Learner (Voyager, 9–12) | D5: Uses the app for maths practice and planets. Has her own PIN. Wants it to feel grown-up. | E5: A cooler look, typed answers, her own goals, privacy from younger siblings. | F5: Cartoonish UI, being treated like a little kid.
A6: Grace | B6: 34 | C6: Parent (account owner) | D6: Mum of Amani and Zawadi. Works full-time, uses an Android phone. Wants screen time that is actually educational and wants to add the family's own world (their farm, their grandparents) to lessons. | E6: Fast set-up; clear progress at a glance; making a custom lesson in under 5 minutes; control of screen time. | F6: Ads, upsells aimed at kids, apps that need constant supervision.
A7: Tom | B7: 41 | C7: Second parent / guardian | D7: Leo's dad. Travels for work, checks progress from his phone and likes to award badges remotely for things Leo does at home. | E7: View progress, award a badge, approve a wish from anywhere. | F7: Being locked out because only one parent set up the account.
A8: Ms Priya | B8: 29 | C8: Teacher (early-years / primary) | D8: Teaches a class of 26 five-and-six-year-olds with 8 shared tablets and a projector. Makes her own weekly spelling and topic lessons. | E8: Quick class set-up; assigning work to groups; seeing who's stuck; reusing and sharing lessons with colleagues. | F8: Kids forgetting passwords; spending lesson time on logins; tools that don't work offline when the Wi-Fi drops.
A9: Joseph | B9: 46 | C9: Adult learner | D9: Grace's uncle. Is improving his reading and wants to learn alongside the grandchildren. Uses the 'Add me too' adult profile. | E9: Adult look; no childish tone; private progress; start at the right level. | F9: Feeling patronised; public comparisons.
A10: Sam | B10: 50 | C10: School administrator | D10: Runs a small primary school with 6 teachers. Buys the school licence and manages teacher seats. | E10: Simple licence and seat management; data-protection paperwork; school-wide reports. | F10: Per-teacher billing chaos; unclear data handling.
A11: Steve | B11: — | C11: Developer / product owner | D11: Builds the product solo with Claude. Needs fast feedback, safe releases and content that can be added without code changes. | E11: Automated checks, reliable deploys, a content pipeline. | F11: Manual, error-prone release steps.

Sheet Screens
A1: Screen | B1: Title | C1: Device | D1: Prototype artboard | E1: Stories (count)
A2: P01 | B2: Welcome | C2: Phone | D2: P01-Welcome.dc.html | E2: =COUNTIF(Backlog!$M$2:$M$229,"*"&A2&"*") -> 2
A3: P02 | B3: Sign up | C3: Phone | D3: P02-SignUp.dc.html | E3: =COUNTIF(Backlog!$M$2:$M$229,"*"&A3&"*") -> 4
A4: P03 | B4: Parental consent | C4: Phone | D4: P03-Consent.dc.html | E4: =COUNTIF(Backlog!$M$2:$M$229,"*"&A4&"*") -> 1
A5: P04 | B5: Add learners | C5: Phone | D5: P04-AddLearners.dc.html | E5: =COUNTIF(Backlog!$M$2:$M$229,"*"&A5&"*") -> 3
A6: P05 | B6: Interests & starting point | C6: Phone | D6: P05-Interests.dc.html | E6: =COUNTIF(Backlog!$M$2:$M$229,"*"&A6&"*") -> 1
A7: P06 | B7: Family settings & hand-over | C7: Phone | D7: P06-FamilySettings.dc.html | E7: =COUNTIF(Backlog!$M$2:$M$229,"*"&A7&"*") -> 2
A8: P08 | B8: Parent home | C8: Phone | D8: P08-ParentHome.dc.html | E8: =COUNTIF(Backlog!$M$2:$M$229,"*"&A8&"*") -> 6
A9: P09 | B9: Child progress | C9: Phone | D9: P09-ChildProgress.dc.html | E9: =COUNTIF(Backlog!$M$2:$M$229,"*"&A9&"*") -> 2
A10: P10 | B10: Lesson Builder: cards | C10: Phone | D10: P10-BuilderCards.dc.html | E10: =COUNTIF(Backlog!$M$2:$M$229,"*"&A10&"*") -> 4
A11: P11 | B11: Lesson Builder: add card | C11: Phone | D11: P11-BuilderAddCard.dc.html | E11: =COUNTIF(Backlog!$M$2:$M$229,"*"&A11&"*") -> 8
A12: P12 | B12: Lesson Builder: template & assign | C12: Phone | D12: P12-BuilderTemplate.dc.html | E12: =COUNTIF(Backlog!$M$2:$M$229,"*"&A12&"*") -> 7
A13: P14 | B13: Badge Studio: design | C13: Phone | D13: P14-BadgeDesign.dc.html | E13: =COUNTIF(Backlog!$M$2:$M$229,"*"&A13&"*") -> 1
... A71: M01 | B71: Moderation queue | C71: Desktop | D71: M01-Moderation.dc.html | E71: =COUNTIF(Backlog!$M$2:$M$229,"*"&A71&"*") -> 5

Sheet Lists
A1: Size | B1: Points | D1: Priority | F1: Milestone | G1: Title | H1: Due | J1: Status
A2: XS | B2: 1 | D2: Must | F2: MVP | G2: Phase 1 — MVP (closed web beta) | H2: 2027-02-26 | J2: To do
A3: S | B3: 2 | D3: Should | F3: P2 | G3: Phase 2 — Beta iteration + Classroom | H3: 2027-04-23 | J3: In progress
A4: M | B4: 3 | D4: Could | F4: P3 | G4: Phase 3 — React Native Android app | H4: 2027-07-30 | J4: In review
A5: L | B5: 5 | F5: P4 | G5: Phase 4 — Breadth + public launch | H5: 2027-11-05 | J5: Done
A6: XL | B6: 8 | F6: P5 | G6: Phase 5 — Post-launch | H6: 2028-06-30 | J6: Blocked
J7: Won't do
